<?xml version="1.0" ?>
<sdf version="1.8">
    <world name="mbari_wec_world">

        <spherical_coordinates>
          <surface_model>EARTH_WGS84</surface_model>
          <world_frame_orientation>ENU</world_frame_orientation>
          <latitude_deg>36.743850</latitude_deg>
          <longitude_deg>-121.876233</longitude_deg>
          <elevation>0.0</elevation>
        </spherical_coordinates>

        <physics name="1ms" type="ignored">
            <max_step_size>.001</max_step_size>
            <real_time_factor>1.0</real_time_factor>
        </physics>

        <light name="sun" type="directional">
            <cast_shadows>true</cast_shadows>
            <pose>0 0 10 0 0 0</pose>
            <diffuse>0.8 0.8 0.8 1</diffuse>
            <specular>0.2 0.2 0.2 1</specular>
            <attenuation>
                <range>1000</range>
                <constant>0.9</constant>
                <linear>0.01</linear>
                <quadratic>0.001</quadratic>
            </attenuation>
            <direction>-0.5 0.1 -0.9</direction>
        </light>

        <model name="Hydraulics Test">
            <pose relative_to="world">0 0 0 0 0 0</pose>
            <!--the pose is relative to the world by default-->

            <link name="Piston">
                <pose relative_to="__model__">0 0 -1 0 0 0</pose>
                <inertial>
                    <mass>910</mass>
                    <inertia>
                        <ixx>10000</ixx>
                        <ixy>0</ixy>
                        <ixz>0</ixz>
                        <iyy>10000</iyy>
                        <iyz>0</iyz>
                        <izz>1000</izz>
                    </inertia>
                </inertial>
                <visual name="visual">
                    <geometry>
                        <cylinder>
                            <radius>.1</radius>
                            <length>2.0</length>
                        </cylinder>
                    </geometry>
                    <!--color-->
                    <material>
                        <ambient>0.0 0.0 1.0 1</ambient>
                        <diffuse>0.0 0.0 1.0 1</diffuse>
                        <specular>0.0 0.0 1.0 1</specular>
                    </material>
                </visual>
            </link>

            <joint name="HydraulicRam" type="prismatic">
                <parent>world</parent>
                <child>Piston</child>
                <pose>0.0 0.0 0.0 0 0 0</pose>
                <axis>
                    <limit>
                        <lower>-20000.0</lower>
                        <upper>20000.0</upper>
                    </limit>
                    <xyz>0.0 0.0 1.0</xyz>
                    <dynamics>
                        <spring_stiffness>18900</spring_stiffness>
                        <spring_reference>0.0</spring_reference>
                        <damping>0.0</damping>
                        <friction>0.0</friction>
                    </dynamics>
                </axis>
            </joint>

            <plugin filename="ElectroHydraulicPTO" name="buoy_gazebo::ElectroHydraulicPTO">
                <PrismaticJointName>HydraulicRam</PrismaticJointName>
                <PistonArea>1.375</PistonArea>
                <HydMotorDisp>0.30</HydMotorDisp>
                <RotorInertia>1</RotorInertia>
            </plugin>
        </model>
    </world>
</sdf>
